{
    "sourceFile": "node_modules/next/dist/server/after/after-context.js",
    "activeCommit": 0,
    "commits": [
        {
            "activePatchIndex": 0,
            "patches": [
                {
                    "date": 1746892866011,
                    "content": "Index: \n===================================================================\n--- \n+++ \n"
                }
            ],
            "date": 1746891704042,
            "name": "cart",
            "content": "\"use strict\";\nObject.defineProperty(exports, \"__esModule\", {\n    value: true\n});\nObject.defineProperty(exports, \"AfterContext\", {\n    enumerable: true,\n    get: function() {\n        return AfterContext;\n    }\n});\nconst _pqueue = /*#__PURE__*/ _interop_require_default(require(\"next/dist/compiled/p-queue\"));\nconst _invarianterror = require(\"../../shared/lib/invariant-error\");\nconst _isthenable = require(\"../../shared/lib/is-thenable\");\nconst _workasyncstorageexternal = require(\"../app-render/work-async-storage.external\");\nconst _revalidationutils = require(\"../revalidation-utils\");\nconst _asynclocalstorage = require(\"../app-render/async-local-storage\");\nconst _workunitasyncstorageexternal = require(\"../app-render/work-unit-async-storage.external\");\nconst _aftertaskasyncstorageexternal = require(\"../app-render/after-task-async-storage.external\");\nfunction _interop_require_default(obj) {\n    return obj && obj.__esModule ? obj : {\n        default: obj\n    };\n}\nclass AfterContext {\n    constructor({ waitUntil, onClose, onTaskError }){\n        this.workUnitStores = new Set();\n        this.waitUntil = waitUntil;\n        this.onClose = onClose;\n        this.onTaskError = onTaskError;\n        this.callbackQueue = new _pqueue.default();\n        this.callbackQueue.pause();\n    }\n    after(task) {\n        if ((0, _isthenable.isThenable)(task)) {\n            if (!this.waitUntil) {\n                errorWaitUntilNotAvailable();\n            }\n            this.waitUntil(task.catch((error)=>this.reportTaskError('promise', error)));\n        } else if (typeof task === 'function') {\n            // TODO(after): implement tracing\n            this.addCallback(task);\n        } else {\n            throw Object.defineProperty(new Error('`after()`: Argument must be a promise or a function'), \"__NEXT_ERROR_CODE\", {\n                value: \"E50\",\n                enumerable: false,\n                configurable: true\n            });\n        }\n    }\n    addCallback(callback) {\n        // if something is wrong, throw synchronously, bubbling up to the `after` callsite.\n        if (!this.waitUntil) {\n            errorWaitUntilNotAvailable();\n        }\n        const workUnitStore = _workunitasyncstorageexternal.workUnitAsyncStorage.getStore();\n        if (workUnitStore) {\n            this.workUnitStores.add(workUnitStore);\n        }\n        const afterTaskStore = _aftertaskasyncstorageexternal.afterTaskAsyncStorage.getStore();\n        // This is used for checking if request APIs can be called inside `after`.\n        // Note that we need to check the phase in which the *topmost* `after` was called (which should be \"action\"),\n        // not the current phase (which might be \"after\" if we're in a nested after).\n        // Otherwise, we might allow `after(() => headers())`, but not `after(() => after(() => headers()))`.\n        const rootTaskSpawnPhase = afterTaskStore ? afterTaskStore.rootTaskSpawnPhase // nested after\n         : workUnitStore == null ? void 0 : workUnitStore.phase // topmost after\n        ;\n        // this should only happen once.\n        if (!this.runCallbacksOnClosePromise) {\n            this.runCallbacksOnClosePromise = this.runCallbacksOnClose();\n            this.waitUntil(this.runCallbacksOnClosePromise);\n        }\n        // Bind the callback to the current execution context (i.e. preserve all currently available ALS-es).\n        // We do this because we want all of these to be equivalent in every regard except timing:\n        //   after(() => x())\n        //   after(x())\n        //   await x()\n        const wrappedCallback = (0, _asynclocalstorage.bindSnapshot)(async ()=>{\n            try {\n                await _aftertaskasyncstorageexternal.afterTaskAsyncStorage.run({\n                    rootTaskSpawnPhase\n                }, ()=>callback());\n            } catch (error) {\n                this.reportTaskError('function', error);\n            }\n        });\n        this.callbackQueue.add(wrappedCallback);\n    }\n    async runCallbacksOnClose() {\n        await new Promise((resolve)=>this.onClose(resolve));\n        return this.runCallbacks();\n    }\n    async runCallbacks() {\n        if (this.callbackQueue.size === 0) return;\n        for (const workUnitStore of this.workUnitStores){\n            workUnitStore.phase = 'after';\n        }\n        const workStore = _workasyncstorageexternal.workAsyncStorage.getStore();\n        if (!workStore) {\n            throw Object.defineProperty(new _invarianterror.InvariantError('Missing workStore in AfterContext.runCallbacks'), \"__NEXT_ERROR_CODE\", {\n                value: \"E547\",\n                enumerable: false,\n                configurable: true\n            });\n        }\n        return (0, _revalidationutils.withExecuteRevalidates)(workStore, ()=>{\n            this.callbackQueue.start();\n            return this.callbackQueue.onIdle();\n        });\n    }\n    reportTaskError(taskKind, error) {\n        // TODO(after): this is fine for now, but will need better intergration with our error reporting.\n        // TODO(after): should we log this if we have a onTaskError callback?\n        console.error(taskKind === 'promise' ? `A promise passed to \\`after()\\` rejected:` : `An error occurred in a function passed to \\`after()\\`:`, error);\n        if (this.onTaskError) {\n            // this is very defensive, but we really don't want anything to blow up in an error handler\n            try {\n                this.onTaskError == null ? void 0 : this.onTaskError.call(this, error);\n            } catch (handlerError) {\n                console.error(Object.defineProperty(new _invarianterror.InvariantError('`onTaskError` threw while handling an error thrown from an `after` task', {\n                    cause: handlerError\n                }), \"__NEXT_ERROR_CODE\", {\n                    value: \"E569\",\n                    enumerable: false,\n                    configurable: true\n                }));\n            }\n        }\n    }\n}\nfunction errorWaitUntilNotAvailable() {\n    throw Object.defineProperty(new Error('`after()` will not work correctly, because `waitUntil` is not available in the current environment.'), \"__NEXT_ERROR_CODE\", {\n        value: \"E91\",\n        enumerable: false,\n        configurable: true\n    });\n}\n\n//# sourceMappingURL=after-context.js.map"
        }
    ]
}